2024-07-16 22:42:50,baseAPI(line:89),ERROR|Traceback (most recent call last):
  File "D:\Program Files\ana\envs\py37\lib\site-packages\urllib3\connection.py", line 159, in _new_conn
    (self._dns_host, self.port), self.timeout, **extra_kw)
  File "D:\Program Files\ana\envs\py37\lib\site-packages\urllib3\util\connection.py", line 80, in create_connection
    raise err
  File "D:\Program Files\ana\envs\py37\lib\site-packages\urllib3\util\connection.py", line 70, in create_connection
    sock.connect(sa)
TimeoutError: [WinError 10060] 由于连接方在一段时间后没有正确答复或连接的主机没有反应，连接尝试失败。

During handling of the above exception, another exception occurred:

Traceback (most recent call last):
  File "D:\Program Files\ana\envs\py37\lib\site-packages\urllib3\connectionpool.py", line 600, in urlopen
    chunked=chunked)
  File "D:\Program Files\ana\envs\py37\lib\site-packages\urllib3\connectionpool.py", line 354, in _make_request
    conn.request(method, url, **httplib_request_kw)
  File "D:\Program Files\ana\envs\py37\lib\http\client.py", line 1281, in request
    self._send_request(method, url, body, headers, encode_chunked)
  File "D:\Program Files\ana\envs\py37\lib\http\client.py", line 1327, in _send_request
    self.endheaders(body, encode_chunked=encode_chunked)
  File "D:\Program Files\ana\envs\py37\lib\http\client.py", line 1276, in endheaders
    self._send_output(message_body, encode_chunked=encode_chunked)
  File "D:\Program Files\ana\envs\py37\lib\http\client.py", line 1036, in _send_output
    self.send(msg)
  File "D:\Program Files\ana\envs\py37\lib\http\client.py", line 976, in send
    self.connect()
  File "D:\Program Files\ana\envs\py37\lib\site-packages\urllib3\connection.py", line 181, in connect
    conn = self._new_conn()
  File "D:\Program Files\ana\envs\py37\lib\site-packages\urllib3\connection.py", line 168, in _new_conn
    self, "Failed to establish a new connection: %s" % e)
urllib3.exceptions.NewConnectionError: <urllib3.connection.HTTPConnection object at 0x0000026F71EE6688>: Failed to establish a new connection: [WinError 10060] 由于连接方在一段时间后没有正确答复或连接的主机没有反应，连接尝试失败。

During handling of the above exception, another exception occurred:

Traceback (most recent call last):
  File "D:\Program Files\ana\envs\py37\lib\site-packages\requests\adapters.py", line 449, in send
    timeout=timeout
  File "D:\Program Files\ana\envs\py37\lib\site-packages\urllib3\connectionpool.py", line 638, in urlopen
    _stacktrace=sys.exc_info()[2])
  File "D:\Program Files\ana\envs\py37\lib\site-packages\urllib3\util\retry.py", line 399, in increment
    raise MaxRetryError(_pool, url, error or ResponseError(cause))
urllib3.exceptions.MaxRetryError: HTTPConnectionPool(host='121.41.14.39', port=8082): Max retries exceeded with url: /account/sLogin/ (Caused by NewConnectionError('<urllib3.connection.HTTPConnection object at 0x0000026F71EE6688>: Failed to establish a new connection: [WinError 10060] 由于连接方在一段时间后没有正确答复或连接的主机没有反应，连接尝试失败。'))

During handling of the above exception, another exception occurred:

Traceback (most recent call last):
  File "D:\Program Files\Delivery_System-master\Delivery_System-master\common\baseAPI.py", line 74, in request_send
    **kwargs)#需要解包 把字典--变成 变量=值写法
  File "D:\Program Files\ana\envs\py37\lib\site-packages\requests\api.py", line 60, in request
    return session.request(method=method, url=url, **kwargs)
  File "D:\Program Files\ana\envs\py37\lib\site-packages\requests\sessions.py", line 533, in request
    resp = self.send(prep, **send_kwargs)
  File "D:\Program Files\ana\envs\py37\lib\site-packages\requests\sessions.py", line 646, in send
    r = adapter.send(request, **kwargs)
  File "D:\Program Files\ana\envs\py37\lib\site-packages\requests\adapters.py", line 516, in send
    raise ConnectionError(e, request=request)
requests.exceptions.ConnectionError: HTTPConnectionPool(host='121.41.14.39', port=8082): Max retries exceeded with url: /account/sLogin/ (Caused by NewConnectionError('<urllib3.connection.HTTPConnection object at 0x0000026F71EE6688>: Failed to establish a new connection: [WinError 10060] 由于连接方在一段时间后没有正确答复或连接的主机没有反应，连接尝试失败。'))

